Files already downloaded and verified
Files already downloaded and verified
    step 0:
Training:   0%|                                                                                                                       | 0/10000 [00:00<?, ?it/s]
Traceback (most recent call last):
  File "models/WGAN.py", line 158, in <module>
    manager.train()
  File "models/WGAN.py", line 103, in train
    real=real.transpose((1,2,0))
  File "/home/zhouqianrui/anaconda3/envs/mc/lib/python3.7/site-packages/jittor/__init__.py", line 658, in transpose
    return origin_transpose(x, dim)
RuntimeError: Wrong inputs arguments, Please refer to examples(help(jt.ops.transpose)).
Types of your inputs are:
 self	= module,
 args	= (Var, tuple, ),
The function declarations are:
 VarHolder* transpose(VarHolder* x,  NanoVector axes=NanoVector())
Failed reason:[38m[f 0106 10:07:35.193082 72 fuse_transpose_op.cc:59] Check failed axes.size()(3) == xdim(4)
Traceback (most recent call last):
  File "models/WGAN.py", line 158, in <module>
    manager.train()
  File "models/WGAN.py", line 103, in train
    real=real.transpose((1,2,0))
  File "/home/zhouqianrui/anaconda3/envs/mc/lib/python3.7/site-packages/jittor/__init__.py", line 658, in transpose
    return origin_transpose(x, dim)
RuntimeError: Wrong inputs arguments, Please refer to examples(help(jt.ops.transpose)).
Types of your inputs are:
 self	= module,
 args	= (Var, tuple, ),
The function declarations are:
 VarHolder* transpose(VarHolder* x,  NanoVector axes=NanoVector())
Failed reason:[38m[f 0106 10:07:35.193082 72 fuse_transpose_op.cc:59] Check failed axes.size()(3) == xdim(4)